[2025-05-28T12:43:11.796+0000] {taskinstance.py:1157} INFO - Dependencies all met for dep_context=non-requeueable deps ti=<TaskInstance: robust_data_lake_pipeline.validate_prerequisites manual__2025-05-28T12:31:44.595551+00:00 [queued]>
[2025-05-28T12:43:11.800+0000] {taskinstance.py:1157} INFO - Dependencies all met for dep_context=requeueable deps ti=<TaskInstance: robust_data_lake_pipeline.validate_prerequisites manual__2025-05-28T12:31:44.595551+00:00 [queued]>
[2025-05-28T12:43:11.800+0000] {taskinstance.py:1359} INFO - Starting attempt 1 of 3
[2025-05-28T12:43:11.805+0000] {taskinstance.py:1380} INFO - Executing <Task(PythonOperator): validate_prerequisites> on 2025-05-28 12:31:44.595551+00:00
[2025-05-28T12:43:11.807+0000] {standard_task_runner.py:57} INFO - Started process 552 to run task
[2025-05-28T12:43:11.809+0000] {standard_task_runner.py:84} INFO - Running: ['***', 'tasks', 'run', 'robust_data_lake_pipeline', 'validate_prerequisites', 'manual__2025-05-28T12:31:44.595551+00:00', '--job-id', '9', '--raw', '--subdir', 'DAGS_FOLDER/pipeline.py', '--cfg-path', '/tmp/tmp_yvvhz8n']
[2025-05-28T12:43:11.813+0000] {standard_task_runner.py:85} INFO - Job 9: Subtask validate_prerequisites
[2025-05-28T12:43:11.818+0000] {logging_mixin.py:151} WARNING - /home/***/.local/lib/python3.8/site-packages/***/settings.py:195 DeprecationWarning: The sql_alchemy_conn option in [core] has been moved to the sql_alchemy_conn option in [database] - the old setting has been used, but please update your config.
[2025-05-28T12:43:11.832+0000] {task_command.py:415} INFO - Running <TaskInstance: robust_data_lake_pipeline.validate_prerequisites manual__2025-05-28T12:31:44.595551+00:00 [running]> on host b769c58f04c0
[2025-05-28T12:43:11.862+0000] {taskinstance.py:1660} INFO - Exporting env vars: AIRFLOW_CTX_DAG_OWNER='***' AIRFLOW_CTX_DAG_ID='robust_data_lake_pipeline' AIRFLOW_CTX_TASK_ID='validate_prerequisites' AIRFLOW_CTX_EXECUTION_DATE='2025-05-28T12:31:44.595551+00:00' AIRFLOW_CTX_TRY_NUMBER='1' AIRFLOW_CTX_DAG_RUN_ID='manual__2025-05-28T12:31:44.595551+00:00'
[2025-05-28T12:43:12.244+0000] {pipeline.py:34} ERROR - S3 connection failed: Unable to locate credentials
[2025-05-28T12:43:12.244+0000] {taskinstance.py:1935} ERROR - Task failed with exception
Traceback (most recent call last):
  File "/home/airflow/.local/lib/python3.8/site-packages/airflow/operators/python.py", line 192, in execute
    return_value = self.execute_callable()
  File "/home/airflow/.local/lib/python3.8/site-packages/airflow/operators/python.py", line 209, in execute_callable
    return self.python_callable(*self.op_args, **self.op_kwargs)
  File "/opt/airflow/dags/pipeline.py", line 31, in validate_prerequisites
    s3_client.list_buckets()
  File "/home/airflow/.local/lib/python3.8/site-packages/botocore/client.py", line 569, in _api_call
    return self._make_api_call(operation_name, kwargs)
  File "/home/airflow/.local/lib/python3.8/site-packages/botocore/client.py", line 1005, in _make_api_call
    http, parsed_response = self._make_request(
  File "/home/airflow/.local/lib/python3.8/site-packages/botocore/client.py", line 1029, in _make_request
    return self._endpoint.make_request(operation_model, request_dict)
  File "/home/airflow/.local/lib/python3.8/site-packages/botocore/endpoint.py", line 119, in make_request
    return self._send_request(request_dict, operation_model)
  File "/home/airflow/.local/lib/python3.8/site-packages/botocore/endpoint.py", line 196, in _send_request
    request = self.create_request(request_dict, operation_model)
  File "/home/airflow/.local/lib/python3.8/site-packages/botocore/endpoint.py", line 132, in create_request
    self._event_emitter.emit(
  File "/home/airflow/.local/lib/python3.8/site-packages/botocore/hooks.py", line 412, in emit
    return self._emitter.emit(aliased_event_name, **kwargs)
  File "/home/airflow/.local/lib/python3.8/site-packages/botocore/hooks.py", line 256, in emit
    return self._emit(event_name, kwargs)
  File "/home/airflow/.local/lib/python3.8/site-packages/botocore/hooks.py", line 239, in _emit
    response = handler(**kwargs)
  File "/home/airflow/.local/lib/python3.8/site-packages/botocore/signers.py", line 106, in handler
    return self.sign(operation_name, request)
  File "/home/airflow/.local/lib/python3.8/site-packages/botocore/signers.py", line 198, in sign
    auth.add_auth(request)
  File "/home/airflow/.local/lib/python3.8/site-packages/botocore/auth.py", line 423, in add_auth
    raise NoCredentialsError()
botocore.exceptions.NoCredentialsError: Unable to locate credentials
[2025-05-28T12:43:12.251+0000] {taskinstance.py:1398} INFO - Marking task as UP_FOR_RETRY. dag_id=robust_data_lake_pipeline, task_id=validate_prerequisites, execution_date=20250528T123144, start_date=20250528T124311, end_date=20250528T124312
[2025-05-28T12:43:12.256+0000] {standard_task_runner.py:104} ERROR - Failed to execute job 9 for task validate_prerequisites (Unable to locate credentials; 552)
[2025-05-28T12:43:12.296+0000] {local_task_job_runner.py:228} INFO - Task exited with return code 1
[2025-05-28T12:43:12.307+0000] {taskinstance.py:2776} INFO - 0 downstream tasks scheduled from follow-on schedule check
