[2025-05-28T12:58:58.874+0000] {taskinstance.py:1157} INFO - Dependencies all met for dep_context=non-requeueable deps ti=<TaskInstance: robust_data_lake_pipeline.validate_prerequisites manual__2025-05-28T12:31:44.595551+00:00 [queued]>
[2025-05-28T12:58:58.877+0000] {taskinstance.py:1157} INFO - Dependencies all met for dep_context=requeueable deps ti=<TaskInstance: robust_data_lake_pipeline.validate_prerequisites manual__2025-05-28T12:31:44.595551+00:00 [queued]>
[2025-05-28T12:58:58.877+0000] {taskinstance.py:1359} INFO - Starting attempt 3 of 3
[2025-05-28T12:58:58.882+0000] {taskinstance.py:1380} INFO - Executing <Task(PythonOperator): validate_prerequisites> on 2025-05-28 12:31:44.595551+00:00
[2025-05-28T12:58:58.884+0000] {standard_task_runner.py:57} INFO - Started process 253 to run task
[2025-05-28T12:58:58.885+0000] {standard_task_runner.py:84} INFO - Running: ['***', 'tasks', 'run', 'robust_data_lake_pipeline', 'validate_prerequisites', 'manual__2025-05-28T12:31:44.595551+00:00', '--job-id', '12', '--raw', '--subdir', 'DAGS_FOLDER/pipeline.py', '--cfg-path', '/tmp/tmpmarb6gaa']
[2025-05-28T12:58:58.886+0000] {standard_task_runner.py:85} INFO - Job 12: Subtask validate_prerequisites
[2025-05-28T12:58:58.893+0000] {logging_mixin.py:151} WARNING - /home/***/.local/lib/python3.8/site-packages/***/settings.py:195 DeprecationWarning: The sql_alchemy_conn option in [core] has been moved to the sql_alchemy_conn option in [database] - the old setting has been used, but please update your config.
[2025-05-28T12:58:58.906+0000] {task_command.py:415} INFO - Running <TaskInstance: robust_data_lake_pipeline.validate_prerequisites manual__2025-05-28T12:31:44.595551+00:00 [running]> on host 99b6cc835ff3
[2025-05-28T12:58:58.934+0000] {taskinstance.py:1660} INFO - Exporting env vars: AIRFLOW_CTX_DAG_OWNER='***' AIRFLOW_CTX_DAG_ID='robust_data_lake_pipeline' AIRFLOW_CTX_TASK_ID='validate_prerequisites' AIRFLOW_CTX_EXECUTION_DATE='2025-05-28T12:31:44.595551+00:00' AIRFLOW_CTX_TRY_NUMBER='3' AIRFLOW_CTX_DAG_RUN_ID='manual__2025-05-28T12:31:44.595551+00:00'
[2025-05-28T12:59:00.127+0000] {pipeline.py:34} ERROR - S3 connection failed: Unable to locate credentials
[2025-05-28T12:59:00.127+0000] {taskinstance.py:1935} ERROR - Task failed with exception
Traceback (most recent call last):
  File "/home/airflow/.local/lib/python3.8/site-packages/airflow/operators/python.py", line 192, in execute
    return_value = self.execute_callable()
  File "/home/airflow/.local/lib/python3.8/site-packages/airflow/operators/python.py", line 209, in execute_callable
    return self.python_callable(*self.op_args, **self.op_kwargs)
  File "/opt/airflow/dags/pipeline.py", line 31, in validate_prerequisites
    s3_client.list_buckets()
  File "/home/airflow/.local/lib/python3.8/site-packages/botocore/client.py", line 569, in _api_call
    return self._make_api_call(operation_name, kwargs)
  File "/home/airflow/.local/lib/python3.8/site-packages/botocore/client.py", line 1005, in _make_api_call
    http, parsed_response = self._make_request(
  File "/home/airflow/.local/lib/python3.8/site-packages/botocore/client.py", line 1029, in _make_request
    return self._endpoint.make_request(operation_model, request_dict)
  File "/home/airflow/.local/lib/python3.8/site-packages/botocore/endpoint.py", line 119, in make_request
    return self._send_request(request_dict, operation_model)
  File "/home/airflow/.local/lib/python3.8/site-packages/botocore/endpoint.py", line 196, in _send_request
    request = self.create_request(request_dict, operation_model)
  File "/home/airflow/.local/lib/python3.8/site-packages/botocore/endpoint.py", line 132, in create_request
    self._event_emitter.emit(
  File "/home/airflow/.local/lib/python3.8/site-packages/botocore/hooks.py", line 412, in emit
    return self._emitter.emit(aliased_event_name, **kwargs)
  File "/home/airflow/.local/lib/python3.8/site-packages/botocore/hooks.py", line 256, in emit
    return self._emit(event_name, kwargs)
  File "/home/airflow/.local/lib/python3.8/site-packages/botocore/hooks.py", line 239, in _emit
    response = handler(**kwargs)
  File "/home/airflow/.local/lib/python3.8/site-packages/botocore/signers.py", line 106, in handler
    return self.sign(operation_name, request)
  File "/home/airflow/.local/lib/python3.8/site-packages/botocore/signers.py", line 198, in sign
    auth.add_auth(request)
  File "/home/airflow/.local/lib/python3.8/site-packages/botocore/auth.py", line 423, in add_auth
    raise NoCredentialsError()
botocore.exceptions.NoCredentialsError: Unable to locate credentials
[2025-05-28T12:59:00.133+0000] {taskinstance.py:1398} INFO - Marking task as FAILED. dag_id=robust_data_lake_pipeline, task_id=validate_prerequisites, execution_date=20250528T123144, start_date=20250528T125858, end_date=20250528T125900
[2025-05-28T12:59:00.138+0000] {standard_task_runner.py:104} ERROR - Failed to execute job 12 for task validate_prerequisites (Unable to locate credentials; 253)
[2025-05-28T12:59:00.148+0000] {local_task_job_runner.py:228} INFO - Task exited with return code 1
[2025-05-28T12:59:00.159+0000] {taskinstance.py:2776} INFO - 0 downstream tasks scheduled from follow-on schedule check
